[2025-02-28 14:00:03,345: INFO: main: >>>>>> stage Data Ingestion stage started <<<<<<]
[2025-02-28 14:00:03,350: INFO: common: Yaml File: config\config.yaml loaded successfully]
[2025-02-28 14:00:03,354: INFO: common: Yaml File: params.yaml loaded successfully]
[2025-02-28 14:00:03,359: INFO: common: Yaml File: schema.yaml loaded successfully]
[2025-02-28 14:00:03,361: INFO: common: Created Directory at: artifacts]
[2025-02-28 14:00:03,362: INFO: common: Created Directory at: artifacts/data_ingestion]
[2025-02-28 14:01:32,459: INFO: data_ingestion: artifacts/data_ingestion/data.zip download! with following info: 
Connection: close
Content-Length: 23329
Cache-Control: max-age=300
Content-Security-Policy: default-src 'none'; style-src 'unsafe-inline'; sandbox
Content-Type: application/zip
ETag: "c69888a4ae59bc5a893392785a938ccd4937981c06ba8a9d6a21aa52b4ab5b6e"
Strict-Transport-Security: max-age=31536000
X-Content-Type-Options: nosniff
X-Frame-Options: deny
X-XSS-Protection: 1; mode=block
X-GitHub-Request-Id: 811F:11C2D:3A716F:94D18B:67C1740D
Accept-Ranges: bytes
Date: Fri, 28 Feb 2025 08:30:06 GMT
Via: 1.1 varnish
X-Served-By: cache-hyd1100030-HYD
X-Cache: MISS
X-Cache-Hits: 0
X-Timer: S1740731406.958014,VS0,VE296
Vary: Authorization,Accept-Encoding,Origin
Access-Control-Allow-Origin: *
Cross-Origin-Resource-Policy: cross-origin
X-Fastly-Request-ID: 96d396c42b0dfddbf8d8b5a7f98c85a512ce6c0c
Expires: Fri, 28 Feb 2025 08:35:06 GMT
Source-Age: 0

]
[2025-02-28 14:01:32,520: INFO: main: >>>>>> stage Data Ingestion stage completed <<<<<<

x==========x]
[2025-02-28 17:02:13,831: INFO: common: Yaml File: config\config.yaml loaded successfully]
[2025-02-28 17:02:13,853: INFO: common: Yaml File: params.yaml loaded successfully]
[2025-02-28 17:02:13,870: INFO: common: Yaml File: schema.yaml loaded successfully]
[2025-02-28 17:02:13,878: INFO: common: Created Directory at: artifacts]
[2025-02-28 17:26:16,896: INFO: common: Yaml File: config\config.yaml loaded successfully]
[2025-02-28 17:26:16,900: INFO: common: Yaml File: params.yaml loaded successfully]
[2025-02-28 17:26:16,906: INFO: common: Yaml File: schema.yaml loaded successfully]
[2025-02-28 17:26:16,908: INFO: common: Created Directory at: artifacts]
[2025-02-28 17:26:16,911: INFO: common: Created Directory at: artifacts/data_validation]
[2025-02-28 17:57:37,804: INFO: main: >>>>>> stage Data Ingestion stage started <<<<<<]
[2025-02-28 17:57:37,806: INFO: common: Yaml File: config\config.yaml loaded successfully]
[2025-02-28 17:57:37,808: INFO: common: Yaml File: params.yaml loaded successfully]
[2025-02-28 17:57:37,811: INFO: common: Yaml File: schema.yaml loaded successfully]
[2025-02-28 17:57:37,812: INFO: common: Created Directory at: artifacts]
[2025-02-28 17:57:37,813: INFO: common: Created Directory at: artifacts/data_ingestion]
[2025-02-28 17:57:37,863: ERROR: main: <urlopen error [Errno 11001] getaddrinfo failed>]
Traceback (most recent call last):
  File "e:\Practice\Practice end to end project\practice1\venv\lib\urllib\request.py", line 1348, in do_open
    h.request(req.get_method(), req.selector, req.data, headers,
  File "e:\Practice\Practice end to end project\practice1\venv\lib\http\client.py", line 1276, in request
    self._send_request(method, url, body, headers, encode_chunked)
  File "e:\Practice\Practice end to end project\practice1\venv\lib\http\client.py", line 1322, in _send_request
    self.endheaders(body, encode_chunked=encode_chunked)
  File "e:\Practice\Practice end to end project\practice1\venv\lib\http\client.py", line 1271, in endheaders
    self._send_output(message_body, encode_chunked=encode_chunked)
  File "e:\Practice\Practice end to end project\practice1\venv\lib\http\client.py", line 1031, in _send_output
    self.send(msg)
  File "e:\Practice\Practice end to end project\practice1\venv\lib\http\client.py", line 969, in send
    self.connect()
  File "e:\Practice\Practice end to end project\practice1\venv\lib\http\client.py", line 1441, in connect
    super().connect()
  File "e:\Practice\Practice end to end project\practice1\venv\lib\http\client.py", line 940, in connect
    self.sock = self._create_connection(
  File "e:\Practice\Practice end to end project\practice1\venv\lib\socket.py", line 824, in create_connection
    for res in getaddrinfo(host, port, 0, SOCK_STREAM):
  File "e:\Practice\Practice end to end project\practice1\venv\lib\socket.py", line 955, in getaddrinfo
    for res in _socket.getaddrinfo(host, port, family, type, proto, flags):
socket.gaierror: [Errno 11001] getaddrinfo failed

During handling of the above exception, another exception occurred:

Traceback (most recent call last):
  File "E:\Practice\Practice end to end project\practice1\main.py", line 10, in <module>
    data_ingestion.initiate_data_ingestion()
  File "E:\Practice\Practice end to end project\practice1\src\datascience\pipeline\data_ingestion_pipeline.py", line 15, in initiate_data_ingestion
    data_ingestion.download_file()
  File "E:\Practice\Practice end to end project\practice1\src\datascience\components\data_ingestion.py", line 17, in download_file
    filename, headers = request.urlretrieve(
  File "e:\Practice\Practice end to end project\practice1\venv\lib\urllib\request.py", line 241, in urlretrieve
    with contextlib.closing(urlopen(url, data)) as fp:
  File "e:\Practice\Practice end to end project\practice1\venv\lib\urllib\request.py", line 216, in urlopen
    return opener.open(url, data, timeout)
  File "e:\Practice\Practice end to end project\practice1\venv\lib\urllib\request.py", line 519, in open
    response = self._open(req, data)
  File "e:\Practice\Practice end to end project\practice1\venv\lib\urllib\request.py", line 536, in _open
    result = self._call_chain(self.handle_open, protocol, protocol +
  File "e:\Practice\Practice end to end project\practice1\venv\lib\urllib\request.py", line 496, in _call_chain
    result = func(*args)
  File "e:\Practice\Practice end to end project\practice1\venv\lib\urllib\request.py", line 1391, in https_open
    return self.do_open(http.client.HTTPSConnection, req,
  File "e:\Practice\Practice end to end project\practice1\venv\lib\urllib\request.py", line 1351, in do_open
    raise URLError(err)
urllib.error.URLError: <urlopen error [Errno 11001] getaddrinfo failed>
[2025-02-28 17:58:09,091: INFO: main: >>>>>> stage Data Ingestion stage started <<<<<<]
[2025-02-28 17:58:09,094: INFO: common: Yaml File: config\config.yaml loaded successfully]
[2025-02-28 17:58:09,095: INFO: common: Yaml File: params.yaml loaded successfully]
[2025-02-28 17:58:09,099: INFO: common: Yaml File: schema.yaml loaded successfully]
[2025-02-28 17:58:09,099: INFO: common: Created Directory at: artifacts]
[2025-02-28 17:58:09,100: INFO: common: Created Directory at: artifacts/data_ingestion]
[2025-02-28 17:58:28,861: ERROR: main: Remote end closed connection without response]
Traceback (most recent call last):
  File "E:\Practice\Practice end to end project\practice1\main.py", line 10, in <module>
    data_ingestion.initiate_data_ingestion()
  File "E:\Practice\Practice end to end project\practice1\src\datascience\pipeline\data_ingestion_pipeline.py", line 15, in initiate_data_ingestion
    data_ingestion.download_file()
  File "E:\Practice\Practice end to end project\practice1\src\datascience\components\data_ingestion.py", line 17, in download_file
    filename, headers = request.urlretrieve(
  File "e:\Practice\Practice end to end project\practice1\venv\lib\urllib\request.py", line 241, in urlretrieve
    with contextlib.closing(urlopen(url, data)) as fp:
  File "e:\Practice\Practice end to end project\practice1\venv\lib\urllib\request.py", line 216, in urlopen
    return opener.open(url, data, timeout)
  File "e:\Practice\Practice end to end project\practice1\venv\lib\urllib\request.py", line 519, in open
    response = self._open(req, data)
  File "e:\Practice\Practice end to end project\practice1\venv\lib\urllib\request.py", line 536, in _open
    result = self._call_chain(self.handle_open, protocol, protocol +
  File "e:\Practice\Practice end to end project\practice1\venv\lib\urllib\request.py", line 496, in _call_chain
    result = func(*args)
  File "e:\Practice\Practice end to end project\practice1\venv\lib\urllib\request.py", line 1391, in https_open
    return self.do_open(http.client.HTTPSConnection, req,
  File "e:\Practice\Practice end to end project\practice1\venv\lib\urllib\request.py", line 1352, in do_open
    r = h.getresponse()
  File "e:\Practice\Practice end to end project\practice1\venv\lib\http\client.py", line 1368, in getresponse
    response.begin()
  File "e:\Practice\Practice end to end project\practice1\venv\lib\http\client.py", line 317, in begin
    version, status, reason = self._read_status()
  File "e:\Practice\Practice end to end project\practice1\venv\lib\http\client.py", line 286, in _read_status
    raise RemoteDisconnected("Remote end closed connection without"
http.client.RemoteDisconnected: Remote end closed connection without response
[2025-02-28 18:05:12,725: INFO: main: >>>>>> stage Data Ingestion stage started <<<<<<]
[2025-02-28 18:05:12,728: INFO: common: Yaml File: config\config.yaml loaded successfully]
[2025-02-28 18:05:12,730: INFO: common: Yaml File: params.yaml loaded successfully]
[2025-02-28 18:05:12,734: INFO: common: Yaml File: schema.yaml loaded successfully]
[2025-02-28 18:05:12,735: INFO: common: Created Directory at: artifacts]
[2025-02-28 18:05:12,736: INFO: common: Created Directory at: artifacts/data_ingestion]
[2025-02-28 18:05:49,317: INFO: data_ingestion: artifacts/data_ingestion/data.zip download! with following info: 
Connection: close
Content-Length: 23329
Cache-Control: max-age=300
Content-Security-Policy: default-src 'none'; style-src 'unsafe-inline'; sandbox
Content-Type: application/zip
ETag: "c69888a4ae59bc5a893392785a938ccd4937981c06ba8a9d6a21aa52b4ab5b6e"
Strict-Transport-Security: max-age=31536000
X-Content-Type-Options: nosniff
X-Frame-Options: deny
X-XSS-Protection: 1; mode=block
X-GitHub-Request-Id: 5E46:20CCE2:C6FB3:1D18D8:67C1AD87
Accept-Ranges: bytes
Date: Fri, 28 Feb 2025 12:35:19 GMT
Via: 1.1 varnish
X-Served-By: cache-hyd1100035-HYD
X-Cache: MISS
X-Cache-Hits: 0
X-Timer: S1740746120.534548,VS0,VE316
Vary: Authorization,Accept-Encoding,Origin
Access-Control-Allow-Origin: *
Cross-Origin-Resource-Policy: cross-origin
X-Fastly-Request-ID: 99af1268098a69882b0ac88774937dc4dcb0792e
Expires: Fri, 28 Feb 2025 12:40:19 GMT
Source-Age: 0

]
[2025-02-28 18:05:49,350: INFO: main: >>>>>> stage Data Ingestion stage completed <<<<<<

x==========x]
[2025-02-28 18:05:49,350: INFO: main: >>>>>> stage Data Validation stage started <<<<<<]
[2025-02-28 18:05:49,353: INFO: common: Yaml File: config\config.yaml loaded successfully]
[2025-02-28 18:05:49,354: INFO: common: Yaml File: params.yaml loaded successfully]
[2025-02-28 18:05:49,359: INFO: common: Yaml File: schema.yaml loaded successfully]
[2025-02-28 18:05:49,360: INFO: common: Created Directory at: artifacts]
[2025-02-28 18:05:49,361: INFO: common: Created Directory at: artifacts/data_validation]
[2025-02-28 18:05:49,361: ERROR: main: 'DataValidationConfig' object is not callable]
Traceback (most recent call last):
  File "E:\Practice\Practice end to end project\practice1\main.py", line 21, in <module>
    data_ingestion.initiate_data_validation()
  File "E:\Practice\Practice end to end project\practice1\src\datascience\pipeline\data_validation.py", line 15, in initiate_data_validation
    data_validation = DataValidation(config = data_validation_config())
TypeError: 'DataValidationConfig' object is not callable
[2025-02-28 18:11:08,293: INFO: main: >>>>>> stage Data Ingestion stage started <<<<<<]
[2025-02-28 18:11:08,295: INFO: common: Yaml File: config\config.yaml loaded successfully]
[2025-02-28 18:11:08,297: INFO: common: Yaml File: params.yaml loaded successfully]
[2025-02-28 18:11:08,300: INFO: common: Yaml File: schema.yaml loaded successfully]
[2025-02-28 18:11:08,301: INFO: common: Created Directory at: artifacts]
[2025-02-28 18:11:08,302: INFO: common: Created Directory at: artifacts/data_ingestion]
[2025-02-28 18:11:35,587: INFO: data_ingestion: artifacts/data_ingestion/data.zip download! with following info: 
Connection: close
Content-Length: 23329
Cache-Control: max-age=300
Content-Security-Policy: default-src 'none'; style-src 'unsafe-inline'; sandbox
Content-Type: application/zip
ETag: "c69888a4ae59bc5a893392785a938ccd4937981c06ba8a9d6a21aa52b4ab5b6e"
Strict-Transport-Security: max-age=31536000
X-Content-Type-Options: nosniff
X-Frame-Options: deny
X-XSS-Protection: 1; mode=block
X-GitHub-Request-Id: 5E46:20CCE2:C6FB3:1D18D8:67C1AD87
Accept-Ranges: bytes
Date: Fri, 28 Feb 2025 12:41:33 GMT
Via: 1.1 varnish
X-Served-By: cache-hyd1100021-HYD
X-Cache: HIT
X-Cache-Hits: 0
X-Timer: S1740746494.662538,VS0,VE276
Vary: Authorization,Accept-Encoding,Origin
Access-Control-Allow-Origin: *
Cross-Origin-Resource-Policy: cross-origin
X-Fastly-Request-ID: 34d77e456ad658281cbe359dc0564871b583c8c7
Expires: Fri, 28 Feb 2025 12:46:33 GMT
Source-Age: 0

]
[2025-02-28 18:11:35,613: INFO: main: >>>>>> stage Data Ingestion stage completed <<<<<<

x==========x]
[2025-02-28 18:11:35,613: INFO: main: >>>>>> stage Data Validation stage started <<<<<<]
[2025-02-28 18:11:35,618: INFO: common: Yaml File: config\config.yaml loaded successfully]
[2025-02-28 18:11:35,619: INFO: common: Yaml File: params.yaml loaded successfully]
[2025-02-28 18:11:35,624: INFO: common: Yaml File: schema.yaml loaded successfully]
[2025-02-28 18:11:35,625: INFO: common: Created Directory at: artifacts]
[2025-02-28 18:11:35,626: INFO: common: Created Directory at: artifacts/data_validation]
[2025-02-28 18:11:35,628: ERROR: main: 'DataValidationConfig' object is not callable]
Traceback (most recent call last):
  File "E:\Practice\Practice end to end project\practice1\main.py", line 22, in <module>
    data_ingestion.initiate_data_validation()
  File "E:\Practice\Practice end to end project\practice1\src\datascience\pipeline\data_validation_pipeline.py", line 15, in initiate_data_validation
    data_validation = DataValidation(config = data_validation_config())
TypeError: 'DataValidationConfig' object is not callable
[2025-03-01 18:40:42,181: INFO: main: >>>>>> stage Data Ingestion stage started <<<<<<]
[2025-03-01 18:40:42,196: INFO: common: Yaml File: config\config.yaml loaded successfully]
[2025-03-01 18:40:42,202: INFO: common: Yaml File: params.yaml loaded successfully]
[2025-03-01 18:40:42,207: INFO: common: Yaml File: schema.yaml loaded successfully]
[2025-03-01 18:40:42,210: INFO: common: Created Directory at: artifacts]
[2025-03-01 18:40:42,211: INFO: common: Created Directory at: artifacts/data_ingestion]
[2025-03-01 18:40:42,950: INFO: data_ingestion: artifacts/data_ingestion/data.zip download! with following info: 
Connection: close
Content-Length: 23329
Cache-Control: max-age=300
Content-Security-Policy: default-src 'none'; style-src 'unsafe-inline'; sandbox
Content-Type: application/zip
ETag: "c69888a4ae59bc5a893392785a938ccd4937981c06ba8a9d6a21aa52b4ab5b6e"
Strict-Transport-Security: max-age=31536000
X-Content-Type-Options: nosniff
X-Frame-Options: deny
X-XSS-Protection: 1; mode=block
X-GitHub-Request-Id: 9C98:130386:336043:8591F9:67C305AD
Accept-Ranges: bytes
Date: Sat, 01 Mar 2025 13:10:42 GMT
Via: 1.1 varnish
X-Served-By: cache-hyd1100020-HYD
X-Cache: HIT
X-Cache-Hits: 0
X-Timer: S1740834643.700059,VS0,VE1
Vary: Authorization,Accept-Encoding,Origin
Access-Control-Allow-Origin: *
Cross-Origin-Resource-Policy: cross-origin
X-Fastly-Request-ID: 4910a2df345936a05b7686d3d0967b44119f1191
Expires: Sat, 01 Mar 2025 13:15:42 GMT
Source-Age: 116

]
[2025-03-01 18:40:42,970: INFO: main: >>>>>> stage Data Ingestion stage completed <<<<<<

x==========x]
[2025-03-01 18:40:42,970: INFO: main: >>>>>> stage Data Validation stage started <<<<<<]
[2025-03-01 18:40:42,973: INFO: common: Yaml File: config\config.yaml loaded successfully]
[2025-03-01 18:40:42,974: INFO: common: Yaml File: params.yaml loaded successfully]
[2025-03-01 18:40:42,978: INFO: common: Yaml File: schema.yaml loaded successfully]
[2025-03-01 18:40:42,979: INFO: common: Created Directory at: artifacts]
[2025-03-01 18:40:42,980: INFO: common: Created Directory at: artifacts/data_validation]
[2025-03-01 18:40:43,012: INFO: main: >>>>>> stage Data Validation stage completed <<<<<<

x==========x]
[2025-03-02 11:55:45,304: INFO: main: >>>>>> stage Data Ingestion stage started <<<<<<]
[2025-03-02 11:55:45,339: INFO: common: Yaml File: config\config.yaml loaded successfully]
[2025-03-02 11:55:45,345: INFO: common: Yaml File: params.yaml loaded successfully]
[2025-03-02 11:55:45,354: INFO: common: Yaml File: schema.yaml loaded successfully]
[2025-03-02 11:55:45,356: INFO: common: Created Directory at: artifacts]
[2025-03-02 11:55:45,357: INFO: common: Created Directory at: artifacts/data_ingestion]
[2025-03-02 11:55:46,302: INFO: data_ingestion: artifacts/data_ingestion/data.zip download! with following info: 
Connection: close
Content-Length: 23329
Cache-Control: max-age=300
Content-Security-Policy: default-src 'none'; style-src 'unsafe-inline'; sandbox
Content-Type: application/zip
ETag: "c69888a4ae59bc5a893392785a938ccd4937981c06ba8a9d6a21aa52b4ab5b6e"
Strict-Transport-Security: max-age=31536000
X-Content-Type-Options: nosniff
X-Frame-Options: deny
X-XSS-Protection: 1; mode=block
X-GitHub-Request-Id: E038:175443:171E3A:48FC0A:67C3F9BD
Accept-Ranges: bytes
Date: Sun, 02 Mar 2025 06:25:46 GMT
Via: 1.1 varnish
X-Served-By: cache-hyd1100022-HYD
X-Cache: HIT
X-Cache-Hits: 1
X-Timer: S1740896746.003768,VS0,VE1
Vary: Authorization,Accept-Encoding,Origin
Access-Control-Allow-Origin: *
Cross-Origin-Resource-Policy: cross-origin
X-Fastly-Request-ID: f10ac753553ff588dc39ada170d1ce343bbf195d
Expires: Sun, 02 Mar 2025 06:30:46 GMT
Source-Age: 41

]
[2025-03-02 11:55:46,352: INFO: main: >>>>>> stage Data Ingestion stage completed <<<<<<

x==========x]
[2025-03-02 11:55:46,353: INFO: main: >>>>>> stage Data Validation stage started <<<<<<]
[2025-03-02 11:55:46,361: INFO: common: Yaml File: config\config.yaml loaded successfully]
[2025-03-02 11:55:46,366: INFO: common: Yaml File: params.yaml loaded successfully]
[2025-03-02 11:55:46,375: INFO: common: Yaml File: schema.yaml loaded successfully]
[2025-03-02 11:55:46,377: INFO: common: Created Directory at: artifacts]
[2025-03-02 11:55:46,379: INFO: common: Created Directory at: artifacts/data_validation]
[2025-03-02 11:55:46,442: INFO: main: >>>>>> stage Data Validation stage completed <<<<<<

x==========x]
[2025-03-02 15:33:43,244: INFO: common: Yaml File: config\config.yaml loaded successfully]
[2025-03-02 15:33:43,251: INFO: common: Yaml File: params.yaml loaded successfully]
[2025-03-02 15:33:43,258: INFO: common: Yaml File: schema.yaml loaded successfully]
[2025-03-02 15:33:43,262: INFO: common: Created Directory at: artifacts]
[2025-03-02 15:34:23,749: INFO: common: Yaml File: config\config.yaml loaded successfully]
[2025-03-02 15:34:23,752: INFO: common: Yaml File: params.yaml loaded successfully]
[2025-03-02 15:34:23,757: INFO: common: Yaml File: schema.yaml loaded successfully]
[2025-03-02 15:34:23,759: INFO: common: Created Directory at: artifacts]
[2025-03-02 15:34:23,760: INFO: common: Created Directory at: artifacts/data_transformation]
[2025-03-02 15:34:23,837: INFO: 3591605836: Splitted data into training and test sets..]
[2025-03-02 15:34:23,838: INFO: 3591605836: (1199, 12)]
[2025-03-02 15:34:23,839: INFO: 3591605836: (400, 12)]
[2025-03-02 15:57:42,952: INFO: main: >>>>>> stage Data Ingestion stage started <<<<<<]
[2025-03-02 15:57:42,965: INFO: common: Yaml File: config\config.yaml loaded successfully]
[2025-03-02 15:57:42,967: INFO: common: Yaml File: params.yaml loaded successfully]
[2025-03-02 15:57:42,970: INFO: common: Yaml File: schema.yaml loaded successfully]
[2025-03-02 15:57:42,970: INFO: common: Created Directory at: artifacts]
[2025-03-02 15:57:42,971: INFO: common: Created Directory at: artifacts/data_ingestion]
[2025-03-02 15:57:43,021: ERROR: main: <urlopen error [Errno 11001] getaddrinfo failed>]
Traceback (most recent call last):
  File "E:\Practice\Practice end to end project\practice1\venv\lib\urllib\request.py", line 1348, in do_open
    h.request(req.get_method(), req.selector, req.data, headers,
  File "E:\Practice\Practice end to end project\practice1\venv\lib\http\client.py", line 1276, in request
    self._send_request(method, url, body, headers, encode_chunked)
  File "E:\Practice\Practice end to end project\practice1\venv\lib\http\client.py", line 1322, in _send_request
    self.endheaders(body, encode_chunked=encode_chunked)
  File "E:\Practice\Practice end to end project\practice1\venv\lib\http\client.py", line 1271, in endheaders
    self._send_output(message_body, encode_chunked=encode_chunked)
  File "E:\Practice\Practice end to end project\practice1\venv\lib\http\client.py", line 1031, in _send_output
    self.send(msg)
  File "E:\Practice\Practice end to end project\practice1\venv\lib\http\client.py", line 969, in send
    self.connect()
  File "E:\Practice\Practice end to end project\practice1\venv\lib\http\client.py", line 1441, in connect
    super().connect()
  File "E:\Practice\Practice end to end project\practice1\venv\lib\http\client.py", line 940, in connect
    self.sock = self._create_connection(
  File "E:\Practice\Practice end to end project\practice1\venv\lib\socket.py", line 824, in create_connection
    for res in getaddrinfo(host, port, 0, SOCK_STREAM):
  File "E:\Practice\Practice end to end project\practice1\venv\lib\socket.py", line 955, in getaddrinfo
    for res in _socket.getaddrinfo(host, port, family, type, proto, flags):
socket.gaierror: [Errno 11001] getaddrinfo failed

During handling of the above exception, another exception occurred:

Traceback (most recent call last):
  File "E:\Practice\Practice end to end project\practice1\main.py", line 10, in <module>
    data_ingestion.initiate_data_ingestion()
  File "E:\Practice\Practice end to end project\practice1\src\datascience\pipeline\data_ingestion_pipeline.py", line 15, in initiate_data_ingestion
    data_ingestion.download_file()
  File "E:\Practice\Practice end to end project\practice1\src\datascience\components\data_ingestion.py", line 17, in download_file
    filename, headers = request.urlretrieve(
  File "E:\Practice\Practice end to end project\practice1\venv\lib\urllib\request.py", line 241, in urlretrieve
    with contextlib.closing(urlopen(url, data)) as fp:
  File "E:\Practice\Practice end to end project\practice1\venv\lib\urllib\request.py", line 216, in urlopen
    return opener.open(url, data, timeout)
  File "E:\Practice\Practice end to end project\practice1\venv\lib\urllib\request.py", line 519, in open
    response = self._open(req, data)
  File "E:\Practice\Practice end to end project\practice1\venv\lib\urllib\request.py", line 536, in _open
    result = self._call_chain(self.handle_open, protocol, protocol +
  File "E:\Practice\Practice end to end project\practice1\venv\lib\urllib\request.py", line 496, in _call_chain
    result = func(*args)
  File "E:\Practice\Practice end to end project\practice1\venv\lib\urllib\request.py", line 1391, in https_open
    return self.do_open(http.client.HTTPSConnection, req,
  File "E:\Practice\Practice end to end project\practice1\venv\lib\urllib\request.py", line 1351, in do_open
    raise URLError(err)
urllib.error.URLError: <urlopen error [Errno 11001] getaddrinfo failed>
[2025-03-02 15:58:57,946: INFO: main: >>>>>> stage Data Ingestion stage started <<<<<<]
[2025-03-02 15:58:57,950: INFO: common: Yaml File: config\config.yaml loaded successfully]
[2025-03-02 15:58:57,951: INFO: common: Yaml File: params.yaml loaded successfully]
[2025-03-02 15:58:57,954: INFO: common: Yaml File: schema.yaml loaded successfully]
[2025-03-02 15:58:57,955: INFO: common: Created Directory at: artifacts]
[2025-03-02 15:58:57,956: INFO: common: Created Directory at: artifacts/data_ingestion]
[2025-03-02 15:58:57,989: ERROR: main: <urlopen error [Errno 11001] getaddrinfo failed>]
Traceback (most recent call last):
  File "E:\Practice\Practice end to end project\practice1\venv\lib\urllib\request.py", line 1348, in do_open
    h.request(req.get_method(), req.selector, req.data, headers,
  File "E:\Practice\Practice end to end project\practice1\venv\lib\http\client.py", line 1276, in request
    self._send_request(method, url, body, headers, encode_chunked)
  File "E:\Practice\Practice end to end project\practice1\venv\lib\http\client.py", line 1322, in _send_request
    self.endheaders(body, encode_chunked=encode_chunked)
  File "E:\Practice\Practice end to end project\practice1\venv\lib\http\client.py", line 1271, in endheaders
    self._send_output(message_body, encode_chunked=encode_chunked)
  File "E:\Practice\Practice end to end project\practice1\venv\lib\http\client.py", line 1031, in _send_output
    self.send(msg)
  File "E:\Practice\Practice end to end project\practice1\venv\lib\http\client.py", line 969, in send
    self.connect()
  File "E:\Practice\Practice end to end project\practice1\venv\lib\http\client.py", line 1441, in connect
    super().connect()
  File "E:\Practice\Practice end to end project\practice1\venv\lib\http\client.py", line 940, in connect
    self.sock = self._create_connection(
  File "E:\Practice\Practice end to end project\practice1\venv\lib\socket.py", line 824, in create_connection
    for res in getaddrinfo(host, port, 0, SOCK_STREAM):
  File "E:\Practice\Practice end to end project\practice1\venv\lib\socket.py", line 955, in getaddrinfo
    for res in _socket.getaddrinfo(host, port, family, type, proto, flags):
socket.gaierror: [Errno 11001] getaddrinfo failed

During handling of the above exception, another exception occurred:

Traceback (most recent call last):
  File "E:\Practice\Practice end to end project\practice1\main.py", line 10, in <module>
    data_ingestion.initiate_data_ingestion()
  File "E:\Practice\Practice end to end project\practice1\src\datascience\pipeline\data_ingestion_pipeline.py", line 15, in initiate_data_ingestion
    data_ingestion.download_file()
  File "E:\Practice\Practice end to end project\practice1\src\datascience\components\data_ingestion.py", line 17, in download_file
    filename, headers = request.urlretrieve(
  File "E:\Practice\Practice end to end project\practice1\venv\lib\urllib\request.py", line 241, in urlretrieve
    with contextlib.closing(urlopen(url, data)) as fp:
  File "E:\Practice\Practice end to end project\practice1\venv\lib\urllib\request.py", line 216, in urlopen
    return opener.open(url, data, timeout)
  File "E:\Practice\Practice end to end project\practice1\venv\lib\urllib\request.py", line 519, in open
    response = self._open(req, data)
  File "E:\Practice\Practice end to end project\practice1\venv\lib\urllib\request.py", line 536, in _open
    result = self._call_chain(self.handle_open, protocol, protocol +
  File "E:\Practice\Practice end to end project\practice1\venv\lib\urllib\request.py", line 496, in _call_chain
    result = func(*args)
  File "E:\Practice\Practice end to end project\practice1\venv\lib\urllib\request.py", line 1391, in https_open
    return self.do_open(http.client.HTTPSConnection, req,
  File "E:\Practice\Practice end to end project\practice1\venv\lib\urllib\request.py", line 1351, in do_open
    raise URLError(err)
urllib.error.URLError: <urlopen error [Errno 11001] getaddrinfo failed>
[2025-03-02 18:28:44,414: INFO: main: >>>>>> stage Data Ingestion stage started <<<<<<]
[2025-03-02 18:28:44,422: INFO: common: Yaml File: config\config.yaml loaded successfully]
[2025-03-02 18:28:44,427: INFO: common: Yaml File: params.yaml loaded successfully]
[2025-03-02 18:28:44,435: INFO: common: Yaml File: schema.yaml loaded successfully]
[2025-03-02 18:28:44,437: INFO: common: Created Directory at: artifacts]
[2025-03-02 18:28:44,439: INFO: common: Created Directory at: artifacts/data_ingestion]
[2025-03-02 18:28:46,075: INFO: data_ingestion: artifacts/data_ingestion/data.zip download! with following info: 
Connection: close
Content-Length: 23329
Cache-Control: max-age=300
Content-Security-Policy: default-src 'none'; style-src 'unsafe-inline'; sandbox
Content-Type: application/zip
ETag: "c69888a4ae59bc5a893392785a938ccd4937981c06ba8a9d6a21aa52b4ab5b6e"
Strict-Transport-Security: max-age=31536000
X-Content-Type-Options: nosniff
X-Frame-Options: deny
X-XSS-Protection: 1; mode=block
X-GitHub-Request-Id: 1656:E2004:5A2B46:F27368:67C45605
Accept-Ranges: bytes
Date: Sun, 02 Mar 2025 12:58:45 GMT
Via: 1.1 varnish
X-Served-By: cache-hyd1100025-HYD
X-Cache: MISS
X-Cache-Hits: 0
X-Timer: S1740920325.158500,VS0,VE285
Vary: Authorization,Accept-Encoding,Origin
Access-Control-Allow-Origin: *
Cross-Origin-Resource-Policy: cross-origin
X-Fastly-Request-ID: fc3af6126b132080fb5769586aaf6b0655a34477
Expires: Sun, 02 Mar 2025 13:03:45 GMT
Source-Age: 0

]
[2025-03-02 18:28:46,121: INFO: main: >>>>>> stage Data Ingestion stage completed <<<<<<

x==========x]
[2025-03-02 18:28:46,122: INFO: main: >>>>>> stage Data Validation stage started <<<<<<]
[2025-03-02 18:28:46,129: INFO: common: Yaml File: config\config.yaml loaded successfully]
[2025-03-02 18:28:46,132: INFO: common: Yaml File: params.yaml loaded successfully]
[2025-03-02 18:28:46,141: INFO: common: Yaml File: schema.yaml loaded successfully]
[2025-03-02 18:28:46,142: INFO: common: Created Directory at: artifacts]
[2025-03-02 18:28:46,144: INFO: common: Created Directory at: artifacts/data_validation]
[2025-03-02 18:28:46,199: INFO: main: >>>>>> stage Data Validation stage completed <<<<<<

x==========x]
[2025-03-02 18:28:46,200: INFO: main: >>>>>> stage Data Transformation Stage started <<<<<<]
[2025-03-02 18:28:46,223: INFO: common: Yaml File: config\config.yaml loaded successfully]
[2025-03-02 18:28:46,226: INFO: common: Yaml File: params.yaml loaded successfully]
[2025-03-02 18:28:46,232: INFO: common: Yaml File: schema.yaml loaded successfully]
[2025-03-02 18:28:46,235: INFO: common: Created Directory at: artifacts]
[2025-03-02 18:28:46,236: INFO: common: Created Directory at: artifacts/data_transformation]
[2025-03-02 18:28:46,294: INFO: data_transformation: Splitted data into training and test sets..]
[2025-03-02 18:28:46,294: INFO: data_transformation: (1199, 12)]
[2025-03-02 18:28:46,295: INFO: data_transformation: (400, 12)]
[2025-03-02 18:28:46,297: INFO: main: >>>>>> stage Data Transformation Stage completed <<<<<<

x==========x]
[2025-03-03 12:08:26,330: INFO: common: Yaml File: config\config.yaml loaded successfully]
[2025-03-03 12:08:26,337: INFO: common: Yaml File: params.yaml loaded successfully]
[2025-03-03 12:08:26,351: INFO: common: Yaml File: schema.yaml loaded successfully]
[2025-03-03 12:08:26,354: INFO: common: Created Directory at: artifacts]
[2025-03-03 12:08:26,356: INFO: common: Created Directory at: artifacts/model_trainer]
[2025-03-03 12:16:45,242: INFO: main: >>>>>> stage Data Ingestion stage started <<<<<<]
[2025-03-03 12:16:45,247: INFO: common: Yaml File: config\config.yaml loaded successfully]
[2025-03-03 12:16:45,249: INFO: common: Yaml File: params.yaml loaded successfully]
[2025-03-03 12:16:45,252: INFO: common: Yaml File: schema.yaml loaded successfully]
[2025-03-03 12:16:45,253: INFO: common: Created Directory at: artifacts]
[2025-03-03 12:16:45,254: INFO: common: Created Directory at: artifacts/data_ingestion]
[2025-03-03 12:16:46,570: INFO: data_ingestion: artifacts/data_ingestion/data.zip download! with following info: 
Connection: close
Content-Length: 23329
Cache-Control: max-age=300
Content-Security-Policy: default-src 'none'; style-src 'unsafe-inline'; sandbox
Content-Type: application/zip
ETag: "c69888a4ae59bc5a893392785a938ccd4937981c06ba8a9d6a21aa52b4ab5b6e"
Strict-Transport-Security: max-age=31536000
X-Content-Type-Options: nosniff
X-Frame-Options: deny
X-XSS-Protection: 1; mode=block
X-GitHub-Request-Id: 5129:1F7638:1C49DE:5541E2:67C55055
Accept-Ranges: bytes
Date: Mon, 03 Mar 2025 06:46:46 GMT
Via: 1.1 varnish
X-Served-By: cache-hyd1100025-HYD
X-Cache: MISS
X-Cache-Hits: 0
X-Timer: S1740984406.954811,VS0,VE282
Vary: Authorization,Accept-Encoding,Origin
Access-Control-Allow-Origin: *
Cross-Origin-Resource-Policy: cross-origin
X-Fastly-Request-ID: 11b769e83cad618fe9cb23493f1251754f001ac8
Expires: Mon, 03 Mar 2025 06:51:46 GMT
Source-Age: 0

]
[2025-03-03 12:16:46,591: INFO: main: >>>>>> stage Data Ingestion stage completed <<<<<<

x==========x]
[2025-03-03 12:16:46,592: INFO: main: >>>>>> stage Data Validation stage started <<<<<<]
[2025-03-03 12:16:46,597: INFO: common: Yaml File: config\config.yaml loaded successfully]
[2025-03-03 12:16:46,599: INFO: common: Yaml File: params.yaml loaded successfully]
[2025-03-03 12:16:46,601: INFO: common: Yaml File: schema.yaml loaded successfully]
[2025-03-03 12:16:46,603: INFO: common: Created Directory at: artifacts]
[2025-03-03 12:16:46,605: INFO: common: Created Directory at: artifacts/data_validation]
[2025-03-03 12:16:46,631: INFO: main: >>>>>> stage Data Validation stage completed <<<<<<

x==========x]
[2025-03-03 12:16:46,632: INFO: main: >>>>>> stage Data Transformation Stage started <<<<<<]
[2025-03-03 12:16:46,645: INFO: common: Yaml File: config\config.yaml loaded successfully]
[2025-03-03 12:16:46,647: INFO: common: Yaml File: params.yaml loaded successfully]
[2025-03-03 12:16:46,649: INFO: common: Yaml File: schema.yaml loaded successfully]
[2025-03-03 12:16:46,651: INFO: common: Created Directory at: artifacts]
[2025-03-03 12:16:46,652: INFO: common: Created Directory at: artifacts/data_transformation]
[2025-03-03 12:16:46,689: INFO: data_transformation: Splitted data into training and test sets..]
[2025-03-03 12:16:46,689: INFO: data_transformation: (1199, 12)]
[2025-03-03 12:16:46,689: INFO: data_transformation: (400, 12)]
[2025-03-03 12:16:46,690: INFO: main: >>>>>> stage Data Transformation Stage completed <<<<<<

x==========x]
[2025-03-03 12:16:46,691: INFO: main: >>>>>> stage Model Trainer stage started <<<<<<]
[2025-03-03 12:16:46,695: INFO: common: Yaml File: config\config.yaml loaded successfully]
[2025-03-03 12:16:46,698: INFO: common: Yaml File: params.yaml loaded successfully]
[2025-03-03 12:16:46,703: INFO: common: Yaml File: schema.yaml loaded successfully]
[2025-03-03 12:16:46,704: INFO: common: Created Directory at: artifacts]
[2025-03-03 12:16:46,706: INFO: common: Created Directory at: artifacts/model_trainer]
[2025-03-03 12:16:46,752: INFO: main: >>>>>> stage Model Trainer stage completed <<<<<<

x==========x]
